Workbook

Sheet Problems
A1: Status | B1: Category | C1: Subtopic | D1: Problem # | E1: Contest ID | F1: Problem Index | G1: Problem Name | H1: Rating | I1: Difficulty | J1: Topics | K1: Estimated Time (mins) | L1: XP | M1: Open Link | N1: Notes
A2: Unsolved | B2: KINGDOM 1 — THE KINGDOM OF ARRAYS | C2: Pattern 1.1 — Basic Array Traversal | D2: 263A | E2: 263 | F2: A | G2: Beautiful Matrix | H2: 800 | I2: Easy | J2: implementation | K2: 15 | L2: 10 | M2: https://codeforces.com/problemset/problem/263/A
A3: Unsolved | B3: KINGDOM 1 — THE KINGDOM OF ARRAYS | C3: Pattern 1.1 — Basic Array Traversal | D3: 266A | E3: 266 | F3: A | G3: Stones on the Table | H3: 800 | I3: Easy | J3: implementation | K3: 15 | L3: 10 | M3: https://codeforces.com/problemset/problem/266/A
A4: Unsolved | B4: KINGDOM 1 — THE KINGDOM OF ARRAYS | C4: Pattern 1.1 — Basic Array Traversal | D4: 339A | E4: 339 | F4: A | G4: Helpful Maths | H4: 800 | I4: Easy | J4: greedy, implementation, sortings, strings | K4: 15 | L4: 10 | M4: https://codeforces.com/problemset/problem/339/A
A5: Unsolved | B5: KINGDOM 1 — THE KINGDOM OF ARRAYS | C5: Pattern 1.1 — Basic Array Traversal | D5: 405A | E5: 405 | F5: A | G5: Gravity Flip | H5: 900 | I5: Easy | J5: greedy, implementation, sortings | K5: 15 | L5: 10 | M5: https://codeforces.com/problemset/problem/405/A
A6: Unsolved | B6: KINGDOM 1 — THE KINGDOM OF ARRAYS | C6: Pattern 1.1 — Basic Array Traversal | D6: 467A | E6: 467 | F6: A | G6: George and Accommodation | H6: 800 | I6: Easy | J6: implementation | K6: 15 | L6: 10 | M6: https://codeforces.com/problemset/problem/467/A
A7: Unsolved | B7: KINGDOM 1 — THE KINGDOM OF ARRAYS | C7: Pattern 1.1 — Basic Array Traversal | D7: 469A | E7: 469 | F7: A | G7: I Wanna Be the Guy | H7: 800 | I7: Easy | J7: greedy, implementation | K7: 15 | L7: 10 | M7: https://codeforces.com/problemset/problem/469/A
A8: Unsolved | B8: KINGDOM 1 — THE KINGDOM OF ARRAYS | C8: Pattern 1.1 — Basic Array Traversal | D8: 479A | E8: 479 | F8: A | G8: Expression | H8: 1000 | I8: Easy+ | J8: brute force, math | K8: 15 | L8: 10 | M8: https://codeforces.com/problemset/problem/479/A
A9: Unsolved | B9: KINGDOM 1 — THE KINGDOM OF ARRAYS | C9: Pattern 1.1 — Basic Array Traversal | D9: 490A | E9: 490 | F9: A | G9: Team Olympiad | H9: 800 | I9: Easy | J9: greedy, implementation, sortings | K9: 15 | L9: 10 | M9: https://codeforces.com/problemset/problem/490/A
A10: Unsolved | B10: KINGDOM 1 — THE KINGDOM OF ARRAYS | C10: Pattern 1.1 — Basic Array Traversal | D10: 501A | E10: 501 | F10: A | G10: Contest | H10: 900 | I10: Easy | J10: implementation | K10: 15 | L10: 10 | M10: https://codeforces.com/problemset/problem/501/A
A11: Unsolved | B11: KINGDOM 1 — THE KINGDOM OF ARRAYS | C11: Pattern 1.1 — Basic Array Traversal | D11: 509A | E11: 509 | F11: A | G11: Maximum in Table | H11: 800 | I11: Easy | J11: brute force, implementation | K11: 15 | L11: 10 | M11: https://codeforces.com/problemset/problem/509/A
A12: Unsolved | B12: KINGDOM 1 — THE KINGDOM OF ARRAYS | C12: Pattern 1.1 — Basic Array Traversal | D12: 510A | E12: 510 | F12: A | G12: Fox And Snake | H12: 800 | I12: Easy | J12: implementation | K12: 15 | L12: 10 | M12: https://codeforces.com/problemset/problem/510/A
A13: Unsolved | B13: KINGDOM 1 — THE KINGDOM OF ARRAYS | C13: Pattern 1.1 — Basic Array Traversal | D13: 581A | E13: 581 | F13: A | G13: Vasya the Hipster | H13: 800 | I13: Easy | J13: implementation, math | K13: 15 | L13: 10 | M13: https://codeforces.com/problemset/problem/581/A
... A127: Unsolved | B127: KINGDOM 1 — THE KINGDOM OF ARRAYS | C127: Pattern 1.5 — Coordinate Compression | D127: 1208B | E127: 1208 | F127: B | G127: Uniqueness | H127: 1500 | I127: Medium+ | J127: binary search, brute force, implementation, two pointers | K127: 40 | L127: 35 | M127: https://codeforces.com/problemset/problem/1208/B
A128: Unsolved | B128: KINGDOM 1 — THE KINGDOM OF ARRAYS | C128: Pattern 1.5 — Coordinate Compression | D128: 1230C | E128: 1230 | F128: C | G128: UNKNOWN | H128: UNKNOWN | I128: UNKNOWN | J128: UNKNOWN | K128: 0 | L128: 0 | M128: https://codeforces.com/problemset/problem/1230/C
A129: Unsolved | B129: KINGDOM 1 — THE KINGDOM OF ARRAYS | C129: Pattern 1.5 — Coordinate Compression | D129: 1324D | E129: 1324 | F129: D | G129: Pair of Topics | H129: 1400 | I129: Medium | J129: binary search, data structures, sortings, two pointers | K129: 40 | L129: 35 | M129: https://codeforces.com/problemset/problem/1324/D
A130: Unsolved | B130: KINGDOM 1 — THE KINGDOM OF ARRAYS | C130: Pattern 1.5 — Coordinate Compression | D130: 1355C | E130: 1355 | F130: C | G130: Count Triangles | H130: 1800 | I130: Hard | J130: binary search, implementation, math, two pointers | K130: 60 | L130: 55 | M130: https://codeforces.com/problemset/problem/1355/C
A131: Unsolved | B131: KINGDOM 1 — THE KINGDOM OF ARRAYS | C131: Pattern 1.5 — Coordinate Compression | D131: 1400C | E131: 1400 | F131: C | G131: Binary String Reconstruction | H131: 1500 | I131: Medium+ | J131: 2-sat, brute force, constructive algorithms, greedy | K131: 40 | L131: 35 | M131: https://codeforces.com/problemset/problem/1400/C
A132: Unsolved | B132: KINGDOM 1 — THE KINGDOM OF ARRAYS | C132: Pattern 1.5 — Coordinate Compression | D132: 1473D | E132: 1473 | F132: D | G132: Program | H132: 1700 | I132: Hard | J132: data structures, dp, implementation, strings | K132: 60 | L132: 55 | M132: https://codeforces.com/problemset/problem/1473/D
A133: Unsolved | B133: KINGDOM 1 — THE KINGDOM OF ARRAYS | C133: Pattern 1.5 — Coordinate Compression | D133: 1490D | E133: 1490 | F133: D | G133: Permutation Transformation | H133: 1200 | I133: Easy+ | J133: dfs and similar, divide and conquer, implementation | K133: 25 | L133: 20 | M133: https://codeforces.com/problemset/problem/1490/D
A134: Unsolved | B134: KINGDOM 1 — THE KINGDOM OF ARRAYS | C134: Pattern 1.5 — Coordinate Compression | D134: 1512D | E134: 1512 | F134: D | G134: Corrupted Array | H134: 1200 | I134: Easy+ | J134: constructive algorithms, data structures, greedy | K134: 25 | L134: 20 | M134: https://codeforces.com/problemset/problem/1512/D
A135: Unsolved | B135: KINGDOM 1 — THE KINGDOM OF ARRAYS | C135: Pattern 1.5 — Coordinate Compression | D135: 1547C | E135: 1547 | F135: C | G135: Pair Programming | H135: 1100 | I135: Easy+ | J135: greedy, two pointers | K135: 25 | L135: 20 | M135: https://codeforces.com/problemset/problem/1547/C
A136: Unsolved | B136: KINGDOM 1 — THE KINGDOM OF ARRAYS | C136: Pattern 1.5 — Coordinate Compression | D136: 1567C | E136: 1567 | F136: C | G136: Carrying Conundrum | H136: 1600 | I136: Medium+ | J136: bitmasks, combinatorics, dp, math | K136: 40 | L136: 35 | M136: https://codeforces.com/problemset/problem/1567/C
A137: Unsolved | B137: KINGDOM 1 — THE KINGDOM OF ARRAYS | C137: Pattern 1.6 — Constructive Arrays | D137: 1251C | E137: 1251 | F137: C | G137: Minimize The Integer | H137: 1600 | I137: Medium+ | J137: greedy, two pointers | K137: 40 | L137: 35 | M137: https://codeforces.com/problemset/problem/1251/C
A138: Unsolved | B138: KINGDOM 1 — THE KINGDOM OF ARRAYS | C138: Pattern 1.6 — Constructive Arrays | D138: 1288D | E138: 1288 | F138: D | G138: Minimax Problem | H138: 2000 | I138: Hard+ | J138: binary search, bitmasks, dp | K138: 90 | L138: 80 | M138: https://codeforces.com/problemset/problem/1288/D
A139: Unsolved | B139: KINGDOM 1 — THE KINGDOM OF ARRAYS | C139: Pattern 1.6 — Constructive Arrays | D139: 1370D | E139: 1370 | F139: D | G139: Odd-Even Subsequence | H139: 2000 | I139: Hard+ | J139: binary search, dp, dsu, greedy, implementation | K139: 90 | L139: 80 | M139: https://codeforces.com/problemset/problem/1370/D
A140: Unsolved | B140: KINGDOM 1 — THE KINGDOM OF ARRAYS | C140: Pattern 1.6 — Constructive Arrays | D140: 1407D | E140: 1407 | F140: D | G140: Discrete Centrifugal Jumps | H140: 2200 | I140: Expert | J140: data structures, dp, graphs | K140: 90 | L140: 80 | M140: https://codeforces.com/problemset/problem/1407/D
... A152: Unsolved | B152: KINGDOM 2 — THE KINGDOM OF PREFIX SUM & DIFFERENCE ARRAY | C152: Pattern 2.1 — 1D Prefix Sum | D152: 816B | E152: 816 | F152: B | G152: Karen and Coffee | H152: 1400 | I152: Medium | J152: binary search, data structures, implementation | K152: 40 | L152: 35 | M152: https://codeforces.com/problemset/problem/816/B
A153: Unsolved | B153: KINGDOM 2 — THE KINGDOM OF PREFIX SUM & DIFFERENCE ARRAY | C153: Pattern 2.1 — 1D Prefix Sum | D153: 1191C | E153: 1191 | F153: C | G153: UNKNOWN | H153: UNKNOWN | I153: UNKNOWN | J153: UNKNOWN | K153: 0 | L153: 0 | M153: https://codeforces.com/problemset/problem/1191/C
A154: Unsolved | B154: KINGDOM 2 — THE KINGDOM OF PREFIX SUM & DIFFERENCE ARRAY | C154: Pattern 2.1 — 1D Prefix Sum | D154: 1272C | E154: 1272 | F154: C | G154: Yet Another Broken Keyboard | H154: 1200 | I154: Easy+ | J154: combinatorics, dp, implementation | K154: 25 | L154: 20 | M154: https://codeforces.com/problemset/problem/1272/C
A155: Unsolved | B155: KINGDOM 2 — THE KINGDOM OF PREFIX SUM & DIFFERENCE ARRAY | C155: Pattern 2.1 — 1D Prefix Sum | D155: 1363A | E155: 1363 | F155: A | G155: Odd Selection | H155: 1200 | I155: Easy+ | J155: brute force, implementation, math | K155: 25 | L155: 20 | M155: https://codeforces.com/problemset/problem/1363/A
A156: Unsolved | B156: KINGDOM 2 — THE KINGDOM OF PREFIX SUM & DIFFERENCE ARRAY | C156: Pattern 2.1 — 1D Prefix Sum | D156: 1392D | E156: 1392 | F156: D | G156: Omkar and Bed Wars | H156: 1700 | I156: Hard | J156: dp, greedy | K156: 60 | L156: 55 | M156: https://codeforces.com/problemset/problem/1392/D
A157: Unsolved | B157: KINGDOM 2 — THE KINGDOM OF PREFIX SUM & DIFFERENCE ARRAY | C157: Pattern 2.1 — 1D Prefix Sum | D157: 1430D | E157: 1430 | F157: D | G157: String Deletion | H157: 1700 | I157: Hard | J157: binary search, data structures, greedy, two pointers | K157: 60 | L157: 55 | M157: https://codeforces.com/problemset/problem/1430/D
A158: Unsolved | B158: KINGDOM 2 — THE KINGDOM OF PREFIX SUM & DIFFERENCE ARRAY | C158: Pattern 2.2 — Prefix Frequency | D158: 1114C | E158: 1114 | F158: C | G158: Trailing Loves (or L'oeufs?) | H158: 1700 | I158: Hard | J158: brute force, implementation, math, number theory | K158: 60 | L158: 55 | M158: https://codeforces.com/problemset/problem/1114/C
A159: Unsolved | B159: KINGDOM 2 — THE KINGDOM OF PREFIX SUM & DIFFERENCE ARRAY | C159: Pattern 2.2 — Prefix Frequency | D159: 1141D | E159: 1141 | F159: D | G159: Colored Boots | H159: 1500 | I159: Medium+ | J159: greedy, implementation | K159: 40 | L159: 35 | M159: https://codeforces.com/problemset/problem/1141/D
A160: Unsolved | B160: KINGDOM 2 — THE KINGDOM OF PREFIX SUM & DIFFERENCE ARRAY | C160: Pattern 2.2 — Prefix Frequency | D160: 1238E | E160: 1238 | F160: E | G160: Keyboard Purchase | H160: 2200 | I160: Expert | J160: bitmasks, dp | K160: 90 | L160: 80 | M160: https://codeforces.com/problemset/problem/1238/E
A161: Unsolved | B161: KINGDOM 2 — THE KINGDOM OF PREFIX SUM & DIFFERENCE ARRAY | C161: Pattern 2.2 — Prefix Frequency | D161: 1285B | E161: 1285 | F161: B | G161: Just Eat It! | H161: 1300 | I161: Medium | J161: dp, greedy, implementation | K161: 25 | L161: 20 | M161: https://codeforces.com/problemset/problem/1285/B
A162: Unsolved | B162: KINGDOM 2 — THE KINGDOM OF PREFIX SUM & DIFFERENCE ARRAY | C162: Pattern 2.2 — Prefix Frequency | D162: 1303C | E162: 1303 | F162: C | G162: Perfect Keyboard | H162: 1600 | I162: Medium+ | J162: dfs and similar, greedy, implementation | K162: 40 | L162: 35 | M162: https://codeforces.com/problemset/problem/1303/C
A163: Unsolved | B163: KINGDOM 2 — THE KINGDOM OF PREFIX SUM & DIFFERENCE ARRAY | C163: Pattern 2.2 — Prefix Frequency | D163: 1437C | E163: 1437 | F163: C | G163: Chef Monocarp | H163: 1800 | I163: Hard | J163: dp, flows, graph matchings, greedy, math, sortings | K163: 60 | L163: 55 | M163: https://codeforces.com/problemset/problem/1437/C
A164: Unsolved | B164: KINGDOM 2 — THE KINGDOM OF PREFIX SUM & DIFFERENCE ARRAY | C164: Pattern 2.2 — Prefix Frequency | D164: 1498C | E164: 1498 | F164: C | G164: Planar Reflections | H164: 1600 | I164: Medium+ | J164: brute force, data structures, dp | K164: 40 | L164: 35 | M164: https://codeforces.com/problemset/problem/1498/C
...

Sheet Kingdom Summary
A1: Kingdom | B1: Patterns | C1: Total Problems | D1: Verified Problems | E1: Solved | F1: Completion % | G1: Total XP | H1: Average Rating
A2: KINGDOM 1 — THE KINGDOM OF ARRAYS | B2: 6 | C2: =COUNTIF(Problems!$B:$B, A2) -> 146 | D2: =COUNTIFS(Problems!$B:$B, A2, Problems!$G:$G, "<>UNKNOWN") -> 145 | E2: =COUNTIFS(Problems!$B:$B, A2, Problems!$A:$A, "Solved") -> 0 | F2: =IF(C2>0, E2/C2, 0) -> 0 | G2: =SUMIF(Problems!$B:$B, A2, Problems!$L:$L) -> 2945 | H2: =AVERAGEIF(Problems!$B:$B, A2, Problems!$H:$H) -> 1086.2069
A3: KINGDOM 2 — THE KINGDOM OF PREFIX SUM & DIFFERENCE ARRAY | B3: 4 | C3: =COUNTIF(Problems!$B:$B, A3) -> 36 | D3: =COUNTIFS(Problems!$B:$B, A3, Problems!$G:$G, "<>UNKNOWN") -> 35 | E3: =COUNTIFS(Problems!$B:$B, A3, Problems!$A:$A, "Solved") -> 0 | F3: =IF(C3>0, E3/C3, 0) -> 0 | G3: =SUMIF(Problems!$B:$B, A3, Problems!$L:$L) -> 1820 | H3: =AVERAGEIF(Problems!$B:$B, A3, Problems!$H:$H) -> 1720
A4: KINGDOM 3 — THE KINGDOM OF TWO POINTERS & SLIDING WINDOW | B4: 4 | C4: =COUNTIF(Problems!$B:$B, A4) -> 33 | D4: =COUNTIFS(Problems!$B:$B, A4, Problems!$G:$G, "<>UNKNOWN") -> 32 | E4: =COUNTIFS(Problems!$B:$B, A4, Problems!$A:$A, "Solved") -> 0 | F4: =IF(C4>0, E4/C4, 0) -> 0 | G4: =SUMIF(Problems!$B:$B, A4, Problems!$L:$L) -> 1355 | H4: =AVERAGEIF(Problems!$B:$B, A4, Problems!$H:$H) -> 1562.5
A5: KINGDOM 4 — THE KINGDOM OF BINARY SEARCH | B5: 4 | C5: =COUNTIF(Problems!$B:$B, A5) -> 16 | D5: =COUNTIFS(Problems!$B:$B, A5, Problems!$G:$G, "<>UNKNOWN") -> 16 | E5: =COUNTIFS(Problems!$B:$B, A5, Problems!$A:$A, "Solved") -> 0 | F5: =IF(C5>0, E5/C5, 0) -> 0 | G5: =SUMIF(Problems!$B:$B, A5, Problems!$L:$L) -> 820 | H5: =AVERAGEIF(Problems!$B:$B, A5, Problems!$H:$H) -> 1731.25
A6: KINGDOM 5 — THE KINGDOM OF SORTING & GREEDY | B6: 5 | C6: =COUNTIF(Problems!$B:$B, A6) -> 39 | D6: =COUNTIFS(Problems!$B:$B, A6, Problems!$G:$G, "<>UNKNOWN") -> 39 | E6: =COUNTIFS(Problems!$B:$B, A6, Problems!$A:$A, "Solved") -> 0 | F6: =IF(C6>0, E6/C6, 0) -> 0 | G6: =SUMIF(Problems!$B:$B, A6, Problems!$L:$L) -> 1660 | H6: =AVERAGEIF(Problems!$B:$B, A6, Problems!$H:$H) -> 1569.2308
A7: KINGDOM 6 — THE KINGDOM OF STRINGS | B7: 6 | C7: =COUNTIF(Problems!$B:$B, A7) -> 52 | D7: =COUNTIFS(Problems!$B:$B, A7, Problems!$G:$G, "<>UNKNOWN") -> 50 | E7: =COUNTIFS(Problems!$B:$B, A7, Problems!$A:$A, "Solved") -> 0 | F7: =IF(C7>0, E7/C7, 0) -> 0 | G7: =SUMIF(Problems!$B:$B, A7, Problems!$L:$L) -> 1790 | H7: =AVERAGEIF(Problems!$B:$B, A7, Problems!$H:$H) -> 1352
A8: KINGDOM 7 — THE KINGDOM OF BIT MANIPULATION | B8: 4 | C8: =COUNTIF(Problems!$B:$B, A8) -> 30 | D8: =COUNTIFS(Problems!$B:$B, A8, Problems!$G:$G, "<>UNKNOWN") -> 27 | E8: =COUNTIFS(Problems!$B:$B, A8, Problems!$A:$A, "Solved") -> 0 | F8: =IF(C8>0, E8/C8, 0) -> 0 | G8: =SUMIF(Problems!$B:$B, A8, Problems!$L:$L) -> 1165 | H8: =AVERAGEIF(Problems!$B:$B, A8, Problems!$H:$H) -> 1474.0741
A9: KINGDOM 8 — THE KINGDOM OF MATHEMATICS & NUMBER THEORY | B9: 6 | C9: =COUNTIF(Problems!$B:$B, A9) -> 69 | D9: =COUNTIFS(Problems!$B:$B, A9, Problems!$G:$G, "<>UNKNOWN") -> 69 | E9: =COUNTIFS(Problems!$B:$B, A9, Problems!$A:$A, "Solved") -> 0 | F9: =IF(C9>0, E9/C9, 0) -> 0 | G9: =SUMIF(Problems!$B:$B, A9, Problems!$L:$L) -> 3120 | H9: =AVERAGEIF(Problems!$B:$B, A9, Problems!$H:$H) -> 1521.7391
A10: KINGDOM 9 — THE KINGDOM OF RECURSION & BACKTRACKING | B10: 4 | C10: =COUNTIF(Problems!$B:$B, A10) -> 34 | D10: =COUNTIFS(Problems!$B:$B, A10, Problems!$G:$G, "<>UNKNOWN") -> 32 | E10: =COUNTIFS(Problems!$B:$B, A10, Problems!$A:$A, "Solved") -> 0 | F10: =IF(C10>0, E10/C10, 0) -> 0 | G10: =SUMIF(Problems!$B:$B, A10, Problems!$L:$L) -> 1365 | H10: =AVERAGEIF(Problems!$B:$B, A10, Problems!$H:$H) -> 1575
A11: KINGDOM 10 — THE KINGDOM OF STACK & MONOTONIC STACK | B11: 4 | C11: =COUNTIF(Problems!$B:$B, A11) -> 30 | D11: =COUNTIFS(Problems!$B:$B, A11, Problems!$G:$G, "<>UNKNOWN") -> 30 | E11: =COUNTIFS(Problems!$B:$B, A11, Problems!$A:$A, "Solved") -> 0 | F11: =IF(C11>0, E11/C11, 0) -> 0 | G11: =SUMIF(Problems!$B:$B, A11, Problems!$L:$L) -> 1570 | H11: =AVERAGEIF(Problems!$B:$B, A11, Problems!$H:$H) -> 1696.6667
A12: KINGDOM 11 — THE KINGDOM OF QUEUE & DEQUE | B12: 4 | C12: =COUNTIF(Problems!$B:$B, A12) -> 31 | D12: =COUNTIFS(Problems!$B:$B, A12, Problems!$G:$G, "<>UNKNOWN") -> 31 | E12: =COUNTIFS(Problems!$B:$B, A12, Problems!$A:$A, "Solved") -> 0 | F12: =IF(C12>0, E12/C12, 0) -> 0 | G12: =SUMIF(Problems!$B:$B, A12, Problems!$L:$L) -> 1380 | H12: =AVERAGEIF(Problems!$B:$B, A12, Problems!$H:$H) -> 1570.9677
A13: KINGDOM 12 — THE KINGDOM OF LINKED LIST & SIMULATION | B13: 4 | C13: =COUNTIF(Problems!$B:$B, A13) -> 28 | D13: =COUNTIFS(Problems!$B:$B, A13, Problems!$G:$G, "<>UNKNOWN") -> 28 | E13: =COUNTIFS(Problems!$B:$B, A13, Problems!$A:$A, "Solved") -> 0 | F13: =IF(C13>0, E13/C13, 0) -> 0 | G13: =SUMIF(Problems!$B:$B, A13, Problems!$L:$L) -> 1065 | H13: =AVERAGEIF(Problems!$B:$B, A13, Problems!$H:$H) -> 1457.1429
... A22: KINGDOM 25 — THE KINGDOM OF GEOMETRY, INTERACTIVE & MISCELLANEOUS | B22: 5 | C22: =COUNTIF(Problems!$B:$B, A22) -> 25 | D22: =COUNTIFS(Problems!$B:$B, A22, Problems!$G:$G, "<>UNKNOWN") -> 24 | E22: =COUNTIFS(Problems!$B:$B, A22, Problems!$A:$A, "Solved") -> 0 | F22: =IF(C22>0, E22/C22, 0) -> 0 | G22: =SUMIF(Problems!$B:$B, A22, Problems!$L:$L) -> 1720 | H22: =AVERAGEIF(Problems!$B:$B, A22, Problems!$H:$H) -> 1891.6667

Sheet Pattern Summary
A1: Kingdom | B1: Pattern | C1: Total Problems | D1: Verified | E1: Solved | F1: Completion % | G1: Average Rating
A2: KINGDOM 1 — THE KINGDOM OF ARRAYS | B2: Pattern 1.1 — Basic Array Traversal | C2: =COUNTIF(Problems!$C:$C, B2) -> 39 | D2: =COUNTIFS(Problems!$C:$C, B2, Problems!$G:$G, "<>UNKNOWN") -> 39 | E2: =COUNTIFS(Problems!$C:$C, B2, Problems!$A:$A, "Solved") -> 0 | F2: =IF(C2>0, E2/C2, 0) -> 0 | G2: =AVERAGEIF(Problems!$C:$C, B2, Problems!$H:$H) -> 810.25641
A3: KINGDOM 1 — THE KINGDOM OF ARRAYS | B3: Pattern 1.2 — Frequency Counting | C3: =COUNTIF(Problems!$C:$C, B3) -> 26 | D3: =COUNTIFS(Problems!$C:$C, B3, Problems!$G:$G, "<>UNKNOWN") -> 26 | E3: =COUNTIFS(Problems!$C:$C, B3, Problems!$A:$A, "Solved") -> 0 | F3: =IF(C3>0, E3/C3, 0) -> 0 | G3: =AVERAGEIF(Problems!$C:$C, B3, Problems!$H:$H) -> 915.38462
A4: KINGDOM 1 — THE KINGDOM OF ARRAYS | B4: Pattern 1.3 — Simulation on Arrays | C4: =COUNTIF(Problems!$C:$C, B4) -> 31 | D4: =COUNTIFS(Problems!$C:$C, B4, Problems!$G:$G, "<>UNKNOWN") -> 31 | E4: =COUNTIFS(Problems!$C:$C, B4, Problems!$A:$A, "Solved") -> 0 | F4: =IF(C4>0, E4/C4, 0) -> 0 | G4: =AVERAGEIF(Problems!$C:$C, B4, Problems!$H:$H) -> 996.77419
A5: KINGDOM 1 — THE KINGDOM OF ARRAYS | B5: Pattern 1.4 — Sorting Based Arrays | C5: =COUNTIF(Problems!$C:$C, B5) -> 24 | D5: =COUNTIFS(Problems!$C:$C, B5, Problems!$G:$G, "<>UNKNOWN") -> 24 | E5: =COUNTIFS(Problems!$C:$C, B5, Problems!$A:$A, "Solved") -> 0 | F5: =IF(C5>0, E5/C5, 0) -> 0 | G5: =AVERAGEIF(Problems!$C:$C, B5, Problems!$H:$H) -> 1266.6667
A6: KINGDOM 1 — THE KINGDOM OF ARRAYS | B6: Pattern 1.5 — Coordinate Compression | C6: =COUNTIF(Problems!$C:$C, B6) -> 15 | D6: =COUNTIFS(Problems!$C:$C, B6, Problems!$G:$G, "<>UNKNOWN") -> 14 | E6: =COUNTIFS(Problems!$C:$C, B6, Problems!$A:$A, "Solved") -> 0 | F6: =IF(C6>0, E6/C6, 0) -> 0 | G6: =AVERAGEIF(Problems!$C:$C, B6, Problems!$H:$H) -> 1500
A7: KINGDOM 1 — THE KINGDOM OF ARRAYS | B7: Pattern 1.6 — Constructive Arrays | C7: =COUNTIF(Problems!$C:$C, B7) -> 11 | D7: =COUNTIFS(Problems!$C:$C, B7, Problems!$G:$G, "<>UNKNOWN") -> 11 | E7: =COUNTIFS(Problems!$C:$C, B7, Problems!$A:$A, "Solved") -> 0 | F7: =IF(C7>0, E7/C7, 0) -> 0 | G7: =AVERAGEIF(Problems!$C:$C, B7, Problems!$H:$H) -> 1800
A8: KINGDOM 2 — THE KINGDOM OF PREFIX SUM & DIFFERENCE ARRAY | B8: Pattern 2.1 — 1D Prefix Sum | C8: =COUNTIF(Problems!$C:$C, B8) -> 10 | D8: =COUNTIFS(Problems!$C:$C, B8, Problems!$G:$G, "<>UNKNOWN") -> 9 | E8: =COUNTIFS(Problems!$C:$C, B8, Problems!$A:$A, "Solved") -> 0 | F8: =IF(C8>0, E8/C8, 0) -> 0 | G8: =AVERAGEIF(Problems!$C:$C, B8, Problems!$H:$H) -> 1366.6667
A9: KINGDOM 2 — THE KINGDOM OF PREFIX SUM & DIFFERENCE ARRAY | B9: Pattern 2.2 — Prefix Frequency | C9: =COUNTIF(Problems!$C:$C, B9) -> 8 | D9: =COUNTIFS(Problems!$C:$C, B9, Problems!$G:$G, "<>UNKNOWN") -> 8 | E9: =COUNTIFS(Problems!$C:$C, B9, Problems!$A:$A, "Solved") -> 0 | F9: =IF(C9>0, E9/C9, 0) -> 0 | G9: =AVERAGEIF(Problems!$C:$C, B9, Problems!$H:$H) -> 1662.5
A10: KINGDOM 2 — THE KINGDOM OF PREFIX SUM & DIFFERENCE ARRAY | B10: Pattern 2.3 — Difference Array | C10: =COUNTIF(Problems!$C:$C, B10) -> 11 | D10: =COUNTIFS(Problems!$C:$C, B10, Problems!$G:$G, "<>UNKNOWN") -> 11 | E10: =COUNTIFS(Problems!$C:$C, B10, Problems!$A:$A, "Solved") -> 0 | F10: =IF(C10>0, E10/C10, 0) -> 0 | G10: =AVERAGEIF(Problems!$C:$C, B10, Problems!$H:$H) -> 1854.5455
A11: KINGDOM 2 — THE KINGDOM OF PREFIX SUM & DIFFERENCE ARRAY | B11: Pattern 2.4 — Prefix XOR | C11: =COUNTIF(Problems!$C:$C, B11) -> 7 | D11: =COUNTIFS(Problems!$C:$C, B11, Problems!$G:$G, "<>UNKNOWN") -> 7 | E11: =COUNTIFS(Problems!$C:$C, B11, Problems!$A:$A, "Solved") -> 0 | F11: =IF(C11>0, E11/C11, 0) -> 0 | G11: =AVERAGEIF(Problems!$C:$C, B11, Problems!$H:$H) -> 2028.5714
A12: KINGDOM 3 — THE KINGDOM OF TWO POINTERS & SLIDING WINDOW | B12: Pattern 3.1 — Classic Two Pointers | C12: =COUNTIF(Problems!$C:$C, B12) -> 12 | D12: =COUNTIFS(Problems!$C:$C, B12, Problems!$G:$G, "<>UNKNOWN") -> 12 | E12: =COUNTIFS(Problems!$C:$C, B12, Problems!$A:$A, "Solved") -> 0 | F12: =IF(C12>0, E12/C12, 0) -> 0 | G12: =AVERAGEIF(Problems!$C:$C, B12, Problems!$H:$H) -> 1491.6667
A13: KINGDOM 3 — THE KINGDOM OF TWO POINTERS & SLIDING WINDOW | B13: Pattern 3.2 — Opposite Direction Pointers | C13: =COUNTIF(Problems!$C:$C, B13) -> 7 | D13: =COUNTIFS(Problems!$C:$C, B13, Problems!$G:$G, "<>UNKNOWN") -> 7 | E13: =COUNTIFS(Problems!$C:$C, B13, Problems!$A:$A, "Solved") -> 0 | F13: =IF(C13>0, E13/C13, 0) -> 0 | G13: =AVERAGEIF(Problems!$C:$C, B13, Problems!$H:$H) -> 1442.8571
... A107: KINGDOM 25 — THE KINGDOM OF GEOMETRY, INTERACTIVE & MISCELLANEOUS | B107: Pattern 25.5 — Mixed Expert Problems | C107: =COUNTIF(Problems!$C:$C, B107) -> 9 | D107: =COUNTIFS(Problems!$C:$C, B107, Problems!$G:$G, "<>UNKNOWN") -> 9 | E107: =COUNTIFS(Problems!$C:$C, B107, Problems!$A:$A, "Solved") -> 0 | F107: =IF(C107>0, E107/C107, 0) -> 0 | G107: =AVERAGEIF(Problems!$C:$C, B107, Problems!$H:$H) -> 2222.2222

Sheet Statistics
A1: Codeforces Master Dataset - Platform Analytics
A3: Metric | B3: Formula / Value | C3: Description
A4: Total Problems | B4: =COUNTA(Problems!D2:D10000) -> 792 | C4: Total unique Codeforces problems in curriculum
A5: Verified Problems | B5: =COUNTIF(Problems!G2:G10000, "<>UNKNOWN") -> 9982 | C5: Problems verified with official Codeforces API
A6: Solved Problems | B6: =COUNTIF(Problems!A2:A10000, "Solved") -> 0 | C6: Number of problems marked as Solved
A7: Remaining Problems | B7: =B4-B6 -> 792 | C7: Unsolved problems remaining in learning roadmap
A8: Total XP Available | B8: =SUM(Problems!L2:L10000) -> 37390 | C8: Total XP points across all verified problems
A9: Average Problem Rating | B9: =AVERAGE(Problems!H2:H10000) -> 1587.3548 | C9: Mean Codeforces rating across verified problems
A10: Highest Rating | B10: =MAX(Problems!H2:H10000) -> 3300 | C10: Maximum difficulty rating in dataset
A11: Lowest Rating | B11: =MIN(Problems!H2:H10000) -> 800 | C11: Minimum difficulty rating in dataset
A12: Average Estimated Time (mins) | B12: =AVERAGE(Problems!K2:K10000) -> 53.800505 | C12: Average expected solving duration per problem
A13: Kingdom Completion Rate | B13: =AVERAGE('Kingdom Summary'!F2:F100) -> 0 | C13: Average completion % across all kingdoms
A14: Pattern Completion Rate | B14: =AVERAGE('Pattern Summary'!F2:F500) -> 0 | C14: Average completion % across all patterns

Sheet Metadata
A1: System Metadata & Mapping Standards
A3: Generation Date: | B3: 2026-07-29 21:52:34
A4: Last Updated: | B4: 2026-07-29 21:52:34
A6: Rating Range | B6: Difficulty Tier | C6: Estimated Time (mins) | D6: XP Points
A7: 800-1000 | B7: Easy | C7: 15 | D7: 10
A8: 1100-1300 | B8: Easy+ | C8: 25 | D8: 20
A9: 1400-1600 | B9: Medium | C9: 40 | D9: 35
A10: 1700-1900 | B10: Hard | C10: 60 | D10: 55
A11: 2000-2200 | B11: Hard+ | C11: 90 | D11: 80
A12: 2300-2500 | B12: Expert | C12: 120 | D12: 110
A13: 2600-3000 | B13: Master | C13: 180 | D13: 150
A14: 3100+ | B14: Master | C14: 240 | D14: 220
A17: Kingdom # | B17: Kingdom Name | C17: Total Patterns
A18: 1 | B18: KINGDOM 1 — THE KINGDOM OF ARRAYS | C18: 6
A19: 2 | B19: KINGDOM 2 — THE KINGDOM OF PREFIX SUM & DIFFERENCE ARRAY | C19: 4
A20: 3 | B20: KINGDOM 3 — THE KINGDOM OF TWO POINTERS & SLIDING WINDOW | C20: 4
A21: 4 | B21: KINGDOM 4 — THE KINGDOM OF BINARY SEARCH | C21: 4
A22: 5 | B22: KINGDOM 5 — THE KINGDOM OF SORTING & GREEDY | C22: 5
A23: 6 | B23: KINGDOM 6 — THE KINGDOM OF STRINGS | C23: 6
A24: 7 | B24: KINGDOM 7 — THE KINGDOM OF BIT MANIPULATION | C24: 4
A25: 8 | B25: KINGDOM 8 — THE KINGDOM OF MATHEMATICS & NUMBER THEORY | C25: 6
A26: 9 | B26: KINGDOM 9 — THE KINGDOM OF RECURSION & BACKTRACKING | C26: 4
A27: 10 | B27: KINGDOM 10 — THE KINGDOM OF STACK & MONOTONIC STACK | C27: 4
A28: 11 | B28: KINGDOM 11 — THE KINGDOM OF QUEUE & DEQUE | C28: 4
A29: 12 | B29: KINGDOM 12 — THE KINGDOM OF LINKED LIST & SIMULATION | C29: 4
... A38: 21 | B38: KINGDOM 25 — THE KINGDOM OF GEOMETRY, INTERACTIVE & MISCELLANEOUS | C38: 5
A41: Kingdom | B41: Pattern Name
A42: KINGDOM 1 — THE KINGDOM OF ARRAYS | B42: Pattern 1.1 — Basic Array Traversal
A43: KINGDOM 1 — THE KINGDOM OF ARRAYS | B43: Pattern 1.2 — Frequency Counting
A44: KINGDOM 1 — THE KINGDOM OF ARRAYS | B44: Pattern 1.3 — Simulation on Arrays
A45: KINGDOM 1 — THE KINGDOM OF ARRAYS | B45: Pattern 1.4 — Sorting Based Arrays
A46: KINGDOM 1 — THE KINGDOM OF ARRAYS | B46: Pattern 1.5 — Coordinate Compression
A47: KINGDOM 1 — THE KINGDOM OF ARRAYS | B47: Pattern 1.6 — Constructive Arrays
A48: KINGDOM 2 — THE KINGDOM OF PREFIX SUM & DIFFERENCE ARRAY | B48: Pattern 2.1 — 1D Prefix Sum
A49: KINGDOM 2 — THE KINGDOM OF PREFIX SUM & DIFFERENCE ARRAY | B49: Pattern 2.2 — Prefix Frequency
A50: KINGDOM 2 — THE KINGDOM OF PREFIX SUM & DIFFERENCE ARRAY | B50: Pattern 2.3 — Difference Array
A51: KINGDOM 2 — THE KINGDOM OF PREFIX SUM & DIFFERENCE ARRAY | B51: Pattern 2.4 — Prefix XOR
A52: KINGDOM 3 — THE KINGDOM OF TWO POINTERS & SLIDING WINDOW | B52: Pattern 3.1 — Classic Two Pointers
... A147: KINGDOM 25 — THE KINGDOM OF GEOMETRY, INTERACTIVE & MISCELLANEOUS | B147: Pattern 25.5 — Mixed Expert Problems
